Workbook

Sheet CARATULA
D7: UNIVERSIDAD NACIONAL DE TRUJILLO
D8: FACULTA DE CIENCA ECONÓMICAS
D9: ESCUELA DE CONTABILIDAD Y FINANZAS
D11: DEMO DAY
D12: "ANÁLISIS DE DATOS DE LA COMPAÑÍA DE MINAS BUENAVENTURA S.A.A"
D14: INTEGRANTES | E14: DOCENTE: | F14: CICLO Y TURNO:
D15: 1. Ferrel Gonzales, Jairo | E15: Dr. Granda Fernandez, Juan Manuel | F15: VI Ciclo - Turno tarde
D16: 2. Geronimo Marrufo, Debora | E16: CURSO:
D17: 3. Gonzales Barrios, Nicol | E17: Contabilidad Gerencial
D18: 4. Guillen Saldaña, Cicely

Sheet Consultar
A1: FORMULARIO DE CONSULTA Y AUDITORIA
A3: Instrucciones: Seleccione o ingrese un código de transacción válido (ej: TX-1001 a TX-1068) en la celda amarilla.
B5: CÓDIGO TRANSACCIÓN: | D5: TX-1001
B7: DETALLES DE LA TRANSACCIÓN
B8: Trimestre Comercial: | D8: =_xlfn.XLOOKUP($D$5, DB_Ventas!$A$4:$A$71, DB_Ventas!$B$4:$B$71, "No encontrado", 0) -> Q1-2025
B9: Unidad Minera: | D9: =_xlfn.XLOOKUP($D$5, DB_Ventas!$A$4:$A$71, DB_Ventas!$C$4:$C$71, "No encontrado", 0) -> Orcopampa
B10: Metal Comercializado: | D10: =_xlfn.XLOOKUP($D$5, DB_Ventas!$A$4:$A$71, DB_Ventas!$D$4:$D$71, "No encontrado", 0) -> Oro
B11: Volumen Comercializado: | D11: =_xlfn.XLOOKUP($D$5, DB_Ventas!$A$4:$A$71, DB_Ventas!$E$4:$E$71, 0, 0) -> 13500
B12: Unidad de Medida: | D12: =_xlfn.XLOOKUP($D$5, DB_Ventas!$A$4:$A$71, DB_Ventas!$F$4:$F$71, "N/A", 0) -> oz
B13: Precio Realizado de Venta: | D13: =_xlfn.XLOOKUP($D$5, DB_Ventas!$A$4:$A$71, DB_Ventas!$G$4:$G$71, 0, 0) -> 3547
B14: Ingresos Brutos Totales: | D14: =_xlfn.XLOOKUP($D$5, DB_Ventas!$A$4:$A$71, DB_Ventas!$H$4:$H$71, 0, 0) -> 47884500
B15: Costo Variable CAS Unitario: | D15: =_xlfn.XLOOKUP($D$5, DB_Ventas!$A$4:$A$71, DB_Ventas!$I$4:$I$71, 0, 0) -> 1560
B16: Costo Variable Total (CV): | D16: =_xlfn.XLOOKUP($D$5, DB_Ventas!$A$4:$A$71, DB_Ventas!$J$4:$J$71, 0, 0) -> 21060000
B17: Margen de Contribución Total: | D17: =_xlfn.XLOOKUP($D$5, DB_Ventas!$A$4:$A$71, DB_Ventas!$L$4:$L$71, 0, 0) -> 26824500
B18: % Margen de Contribución (%MC): | D18: =_xlfn.XLOOKUP($D$5, DB_Ventas!$A$4:$A$71, DB_Ventas!$M$4:$M$71, 0, 0) -> 0.56019171

Sheet DATOS CENTRALES
A1: DATOS CENTRALES 2025
A3: 1. COSTO FIJO COMÚN CORPORATIVO ANUAL
A4: SUPUESTO | B4: VALOR
A5: Costos Fijos Totales Comunes: | B5: 289700000 | C5: Comprende Exploraciones en unidades operativas, Administración, Ventas y Deducciones Comerciales.
A7: MATRIZ DE SEGREGACIÓN: PRECIOS REALIZADOS Y COSTOS VARIABLES
A8: MINA | B8: METAL | C8: PRECIO REALIZADO | D8: UNIDAD MEDIDA | E8: COSTO VARIABLE | F8: LLAVE BÚSQUEDA | G8: COMPLEJIDAD X METAL
A9: Orcopampa | B9: Oro | C9: 3547 | D9: oz | E9: 1560 | F9: =A9&"_"&B9 -> Orcopampa_Oro | G9: 0.08
A10: Orcopampa | B10: Plata | C10: 41.87 | D10: oz | E10: 25 | F10: =A10&"_"&B10 -> Orcopampa_Plata | G10: 0.01
A11: Tambomayo | B11: Oro | C11: 3547 | D11: oz | E11: 2678 | F11: =A11&"_"&B11 -> Tambomayo_Oro | G11: 0.1
A12: Tambomayo | B12: Plata | C12: 41.87 | D12: oz | E12: 27.33 | F12: =A12&"_"&B12 -> Tambomayo_Plata | G12: 0.04
A13: Tambomayo | B13: Plomo | C13: 1912 | D13: MT | E13: 1250 | F13: =A13&"_"&B13 -> Tambomayo_Plomo | G13: 0.02
A14: Tambomayo | B14: Zinc | C14: 2844 | D14: MT | E14: 1560 | F14: =A14&"_"&B14 -> Tambomayo_Zinc | G14: 0.02
A15: Uchucchacua & Yumpag | B15: Plata | C15: 41.87 | D15: oz | E15: 15.21 | F15: =A15&"_"&B15 -> Uchucchacua & Yumpag_Plata | G15: 0.22
A16: Uchucchacua & Yumpag | B16: Plomo | C16: 1912 | D16: MT | E16: 582 | F16: =A16&"_"&B16 -> Uchucchacua & Yumpag_Plomo | G16: 0.04
A17: Uchucchacua & Yumpag | B17: Zinc | C17: 2844 | D17: MT | E17: 1126 | F17: =A17&"_"&B17 -> Uchucchacua & Yumpag_Zinc | G17: 0.05
A18: El Brocal | B18: Cobre | C18: 10071 | D18: MT | E18: 6435 | F18: =A18&"_"&B18 -> El Brocal_Cobre | G18: 0.22
A19: El Brocal | B19: Plata | C19: 41.87 | D19: oz | E19: 19.07 | F19: =A19&"_"&B19 -> El Brocal_Plata | G19: 0.03
A20: Julcani | B20: Plata | C20: 41.87 | D20: oz | E20: 26.34 | F20: =A20&"_"&B20 -> Julcani_Plata | G20: 0.02
... A25: Coimolache | B25: Plata | C25: 41.87 | D25: oz | E25: 30.97 | F25: =A25&"_"&B25 -> Coimolache_Plata | G25: 0.03
A27: ESTRUCTURA DE COSTOS FIJOS COMUNES
A28: Rubro Corporativo | B28: Descripción | C28: Importe Anual (USD) | D28: % del Total
A29: Exploraciones Unidades Operativas | B29: Campañas de perforación diamantina e infraestructura | C29: 51906000 | D29: =+C29/$C$33 -> 0.17917156
A30: Gastos de Administración | B30: Oficinas centrales Las Begonias, sistemas y gerencias | C30: 87100000 | D30: =+C30/$C$33 -> 0.30065585
A31: Gastos de Ventas | B31: Fletes terrestres, seguros de transporte y aduanas | C31: 28694000 | D31: =+C31/$C$33 -> 0.09904729
A32: Deducciones Comerciales | B32: Cargos de maquila, refinación y penalidades en plantas | C32: 122000000 | D32: =+C32/$C$33 -> 0.4211253
B33: TOTAL COSTOS FIJOS COMUNES | C33: =SUM(C29:C32) -> 289700000 | D33: =SUM(D29:D32) -> 1

Sheet DB_Ventas
A1: BASE DE DATOS TRANSACCIONAL DE VENTAS DE MINERA BUENAVENTURA S.A.A. (2025)
A2: Datos extraidos de informes públicos de Minera Buenaventura a periodo trimestral según volumen
A3: ID TRANSAC | B3: TRIMESTRE | C3: UNIDAD MINERA | D3: METAL | E3: VOLUMEN VENDIDO | F3: UNIDAD MEDIDA | G3: PRECIO UNITARIO (USD) | H3: INGRESO BRUTO (USD) | I3: CV UNITARIO | J3: COSTO VARIABLE TOTAL (USD) | K3: MC UNITARIO (USD) | L3: MC TOTAL (USD) | M3: % MC | N3: COMPLEJIDAD X METAL UNITARIO | O3: COMPLEJIDAD X METAL total
A4: TX-1001 | B4: Q1-2025 | C4: Orcopampa | D4: Oro | E4: 13500 | F4: =_xlfn.XLOOKUP(D4,'DATOS CENTRALES'!$B$9:$B$25,'DATOS CENTRALES'!$D$9:$D$25,, ) -> oz | G4: =_xlfn.XLOOKUP(D4,'DATOS CENTRALES'!$B$9:$B$25,'DATOS CENTRALES'!$C$9:$C$25) -> 3547 | H4: =+Tabla1[[#This Row],[VOLUMEN VENDIDO]]*Tabla1[[#This Row],[PRECIO UNITARIO (USD)]] -> 47884500 | I4: =_xlfn.XLOOKUP(C4&"_"&D4, 'DATOS CENTRALES'!$F$9:$F$25, 'DATOS CENTRALES'!$E$9:$E$25, 0, 0) -> 1560 | J4: =Tabla1[[#This Row],[CV UNITARIO]]*Tabla1[[#This Row],[VOLUMEN VENDIDO]] -> 21060000 | K4: =+Tabla1[[#This Row],[PRECIO UNITARIO (USD)]]-Tabla1[[#This Row],[CV UNITARIO]] -> 1987 | L4: =+Tabla1[[#This Row],[INGRESO BRUTO (USD)]]-Tabla1[[#This Row],[COSTO VARIABLE TOTAL (USD)]] -> 26824500 | M4: =+Tabla1[[#This Row],[MC TOTAL (USD)]]/Tabla1[[#This Row],[INGRESO BRUTO (USD)]] -> 0.56019171 | N4: =+IFERROR(INDEX('Consolidados x MINERA'!$G$6:$G$11,MATCH(Tabla1[[#This Row],[UNIDAD MINERA]],'Consolidados x MINERA'!$A$6:$A$11,0))*Tabla1[[#This Row],[INGRESO BRUTO (USD)]]/SUMIFS(Tabla1[INGRESO BRUTO (USD)],Tabla1[UNIDAD MINERA],Tabla1[[#This Row],[UNIDAD MINERA]])/Tabla1[[#This Row],[VOLUMEN VENDIDO]],0) -> 0.13429139 | O4: =+Tabla1[[#This Row],[COMPLEJIDAD X METAL UNITARIO]]*Tabla1[[#This Row],[VOLUMEN VENDIDO]] -> 1812.9337
A5: TX-1002 | B5: Q2-2025 | C5: Orcopampa | D5: Oro | E5: 14200 | F5: =_xlfn.XLOOKUP(D5,'DATOS CENTRALES'!$B$9:$B$25,'DATOS CENTRALES'!$D$9:$D$25,, ) -> oz | G5: =_xlfn.XLOOKUP(D5,'DATOS CENTRALES'!$B$9:$B$25,'DATOS CENTRALES'!$C$9:$C$25) -> 3547 | H5: =+Tabla1[[#This Row],[VOLUMEN VENDIDO]]*Tabla1[[#This Row],[PRECIO UNITARIO (USD)]] -> 50367400 | I5: =_xlfn.XLOOKUP(C5&"_"&D5, 'DATOS CENTRALES'!$F$9:$F$25, 'DATOS CENTRALES'!$E$9:$E$25, 0, 0) -> 1560 | J5: =Tabla1[[#This Row],[CV UNITARIO]]*Tabla1[[#This Row],[VOLUMEN VENDIDO]] -> 22152000 | K5: =+Tabla1[[#This Row],[PRECIO UNITARIO (USD)]]-Tabla1[[#This Row],[CV UNITARIO]] -> 1987 | L5: =+Tabla1[[#This Row],[INGRESO BRUTO (USD)]]-Tabla1[[#This Row],[COSTO VARIABLE TOTAL (USD)]] -> 28215400 | M5: =+Tabla1[[#This Row],[MC TOTAL (USD)]]/Tabla1[[#This Row],[INGRESO BRUTO (USD)]] -> 0.56019171 | N5: =+IFERROR(INDEX('Consolidados x MINERA'!$G$6:$G$11,MATCH(Tabla1[[#This Row],[UNIDAD MINERA]],'Consolidados x MINERA'!$A$6:$A$11,0))*Tabla1[[#This Row],[INGRESO BRUTO (USD)]]/SUMIFS(Tabla1[INGRESO BRUTO (USD)],Tabla1[UNIDAD MINERA],Tabla1[[#This Row],[UNIDAD MINERA]])/Tabla1[[#This Row],[VOLUMEN VENDIDO]],0) -> 0.13429139 | O5: =+Tabla1[[#This Row],[COMPLEJIDAD X METAL UNITARIO]]*Tabla1[[#This Row],[VOLUMEN VENDIDO]] -> 1906.9377
A6: TX-1003 | B6: Q3-2025 | C6: Orcopampa | D6: Oro | E6: 13800 | F6: =_xlfn.XLOOKUP(D6,'DATOS CENTRALES'!$B$9:$B$25,'DATOS CENTRALES'!$D$9:$D$25,, ) -> oz | G6: =_xlfn.XLOOKUP(D6,'DATOS CENTRALES'!$B$9:$B$25,'DATOS CENTRALES'!$C$9:$C$25) -> 3547 | H6: =+Tabla1[[#This Row],[VOLUMEN VENDIDO]]*Tabla1[[#This Row],[PRECIO UNITARIO (USD)]] -> 48948600 | I6: =_xlfn.XLOOKUP(C6&"_"&D6, 'DATOS CENTRALES'!$F$9:$F$25, 'DATOS CENTRALES'!$E$9:$E$25, 0, 0) -> 1560 | J6: =Tabla1[[#This Row],[CV UNITARIO]]*Tabla1[[#This Row],[VOLUMEN VENDIDO]] -> 21528000 | K6: =+Tabla1[[#This Row],[PRECIO UNITARIO (USD)]]-Tabla1[[#This Row],[CV UNITARIO]] -> 1987 | L6: =+Tabla1[[#This Row],[INGRESO BRUTO (USD)]]-Tabla1[[#This Row],[COSTO VARIABLE TOTAL (USD)]] -> 27420600 | M6: =+Tabla1[[#This Row],[MC TOTAL (USD)]]/Tabla1[[#This Row],[INGRESO BRUTO (USD)]] -> 0.56019171 | N6: =+IFERROR(INDEX('Consolidados x MINERA'!$G$6:$G$11,MATCH(Tabla1[[#This Row],[UNIDAD MINERA]],'Consolidados x MINERA'!$A$6:$A$11,0))*Tabla1[[#This Row],[INGRESO BRUTO (USD)]]/SUMIFS(Tabla1[INGRESO BRUTO (USD)],Tabla1[UNIDAD MINERA],Tabla1[[#This Row],[UNIDAD MINERA]])/Tabla1[[#This Row],[VOLUMEN VENDIDO]],0) -> 0.13429139 | O6: =+Tabla1[[#This Row],[COMPLEJIDAD X METAL UNITARIO]]*Tabla1[[#This Row],[VOLUMEN VENDIDO]] -> 1853.2212
A7: TX-1004 | B7: Q4-2025 | C7: Orcopampa | D7: Oro | E7: 14132 | F7: =_xlfn.XLOOKUP(D7,'DATOS CENTRALES'!$B$9:$B$25,'DATOS CENTRALES'!$D$9:$D$25,, ) -> oz | G7: =_xlfn.XLOOKUP(D7,'DATOS CENTRALES'!$B$9:$B$25,'DATOS CENTRALES'!$C$9:$C$25) -> 3547 | H7: =+Tabla1[[#This Row],[VOLUMEN VENDIDO]]*Tabla1[[#This Row],[PRECIO UNITARIO (USD)]] -> 50126204 | I7: =_xlfn.XLOOKUP(C7&"_"&D7, 'DATOS CENTRALES'!$F$9:$F$25, 'DATOS CENTRALES'!$E$9:$E$25, 0, 0) -> 1560 | J7: =Tabla1[[#This Row],[CV UNITARIO]]*Tabla1[[#This Row],[VOLUMEN VENDIDO]] -> 22045920 | K7: =+Tabla1[[#This Row],[PRECIO UNITARIO (USD)]]-Tabla1[[#This Row],[CV UNITARIO]] -> 1987 | L7: =+Tabla1[[#This Row],[INGRESO BRUTO (USD)]]-Tabla1[[#This Row],[COSTO VARIABLE TOTAL (USD)]] -> 28080284 | M7: =+Tabla1[[#This Row],[MC TOTAL (USD)]]/Tabla1[[#This Row],[INGRESO BRUTO (USD)]] -> 0.56019171 | N7: =+IFERROR(INDEX('Consolidados x MINERA'!$G$6:$G$11,MATCH(Tabla1[[#This Row],[UNIDAD MINERA]],'Consolidados x MINERA'!$A$6:$A$11,0))*Tabla1[[#This Row],[INGRESO BRUTO (USD)]]/SUMIFS(Tabla1[INGRESO BRUTO (USD)],Tabla1[UNIDAD MINERA],Tabla1[[#This Row],[UNIDAD MINERA]])/Tabla1[[#This Row],[VOLUMEN VENDIDO]],0) -> 0.13429139 | O7: =+Tabla1[[#This Row],[COMPLEJIDAD X METAL UNITARIO]]*Tabla1[[#This Row],[VOLUMEN VENDIDO]] -> 1897.8059
A8: TX-1005 | B8: Q1-2025 | C8: Orcopampa | D8: Plata | E8: 4500 | F8: =_xlfn.XLOOKUP(D8,'DATOS CENTRALES'!$B$9:$B$25,'DATOS CENTRALES'!$D$9:$D$25,, ) -> oz | G8: =_xlfn.XLOOKUP(D8,'DATOS CENTRALES'!$B$9:$B$25,'DATOS CENTRALES'!$C$9:$C$25) -> 41.87 | H8: =+Tabla1[[#This Row],[VOLUMEN VENDIDO]]*Tabla1[[#This Row],[PRECIO UNITARIO (USD)]] -> 188415 | I8: =_xlfn.XLOOKUP(C8&"_"&D8, 'DATOS CENTRALES'!$F$9:$F$25, 'DATOS CENTRALES'!$E$9:$E$25, 0, 0) -> 25 | J8: =Tabla1[[#This Row],[CV UNITARIO]]*Tabla1[[#This Row],[VOLUMEN VENDIDO]] -> 112500 | K8: =+Tabla1[[#This Row],[PRECIO UNITARIO (USD)]]-Tabla1[[#This Row],[CV UNITARIO]] -> 16.87 | L8: =+Tabla1[[#This Row],[INGRESO BRUTO (USD)]]-Tabla1[[#This Row],[COSTO VARIABLE TOTAL (USD)]] -> 75915 | M8: =+Tabla1[[#This Row],[MC TOTAL (USD)]]/Tabla1[[#This Row],[INGRESO BRUTO (USD)]] -> 0.40291378 | N8: =+IFERROR(INDEX('Consolidados x MINERA'!$G$6:$G$11,MATCH(Tabla1[[#This Row],[UNIDAD MINERA]],'Consolidados x MINERA'!$A$6:$A$11,0))*Tabla1[[#This Row],[INGRESO BRUTO (USD)]]/SUMIFS(Tabla1[INGRESO BRUTO (USD)],Tabla1[UNIDAD MINERA],Tabla1[[#This Row],[UNIDAD MINERA]])/Tabla1[[#This Row],[VOLUMEN VENDIDO]],0) -> 0.0015852214 | O8: =+Tabla1[[#This Row],[COMPLEJIDAD X METAL UNITARIO]]*Tabla1[[#This Row],[VOLUMEN VENDIDO]] -> 7.1334964
A9: TX-1006 | B9: Q2-2025 | C9: Orcopampa | D9: Plata | E9: 4800 | F9: =_xlfn.XLOOKUP(D9,'DATOS CENTRALES'!$B$9:$B$25,'DATOS CENTRALES'!$D$9:$D$25,, ) -> oz | G9: =_xlfn.XLOOKUP(D9,'DATOS CENTRALES'!$B$9:$B$25,'DATOS CENTRALES'!$C$9:$C$25) -> 41.87 | H9: =+Tabla1[[#This Row],[VOLUMEN VENDIDO]]*Tabla1[[#This Row],[PRECIO UNITARIO (USD)]] -> 200976 | I9: =_xlfn.XLOOKUP(C9&"_"&D9, 'DATOS CENTRALES'!$F$9:$F$25, 'DATOS CENTRALES'!$E$9:$E$25, 0, 0) -> 25 | J9: =Tabla1[[#This Row],[CV UNITARIO]]*Tabla1[[#This Row],[VOLUMEN VENDIDO]] -> 120000 | K9: =+Tabla1[[#This Row],[PRECIO UNITARIO (USD)]]-Tabla1[[#This Row],[CV UNITARIO]] -> 16.87 | L9: =+Tabla1[[#This Row],[INGRESO BRUTO (USD)]]-Tabla1[[#This Row],[COSTO VARIABLE TOTAL (USD)]] -> 80976 | M9: =+Tabla1[[#This Row],[MC TOTAL (USD)]]/Tabla1[[#This Row],[INGRESO BRUTO (USD)]] -> 0.40291378 | N9: =+IFERROR(INDEX('Consolidados x MINERA'!$G$6:$G$11,MATCH(Tabla1[[#This Row],[UNIDAD MINERA]],'Consolidados x MINERA'!$A$6:$A$11,0))*Tabla1[[#This Row],[INGRESO BRUTO (USD)]]/SUMIFS(Tabla1[INGRESO BRUTO (USD)],Tabla1[UNIDAD MINERA],Tabla1[[#This Row],[UNIDAD MINERA]])/Tabla1[[#This Row],[VOLUMEN VENDIDO]],0) -> 0.0015852214 | O9: =+Tabla1[[#This Row],[COMPLEJIDAD X METAL UNITARIO]]*Tabla1[[#This Row],[VOLUMEN VENDIDO]] -> 7.6090629
A10: TX-1007 | B10: Q3-2025 | C10: Orcopampa | D10: Plata | E10: 4400 | F10: =_xlfn.XLOOKUP(D10,'DATOS CENTRALES'!$B$9:$B$25,'DATOS CENTRALES'!$D$9:$D$25,, ) -> oz | G10: =_xlfn.XLOOKUP(D10,'DATOS CENTRALES'!$B$9:$B$25,'DATOS CENTRALES'!$C$9:$C$25) -> 41.87 | H10: =+Tabla1[[#This Row],[VOLUMEN VENDIDO]]*Tabla1[[#This Row],[PRECIO UNITARIO (USD)]] -> 184228 | I10: =_xlfn.XLOOKUP(C10&"_"&D10, 'DATOS CENTRALES'!$F$9:$F$25, 'DATOS CENTRALES'!$E$9:$E$25, 0, 0) -> 25 | J10: =Tabla1[[#This Row],[CV UNITARIO]]*Tabla1[[#This Row],[VOLUMEN VENDIDO]] -> 110000 | K10: =+Tabla1[[#This Row],[PRECIO UNITARIO (USD)]]-Tabla1[[#This Row],[CV UNITARIO]] -> 16.87 | L10: =+Tabla1[[#This Row],[INGRESO BRUTO (USD)]]-Tabla1[[#This Row],[COSTO VARIABLE TOTAL (USD)]] -> 74228 | M10: =+Tabla1[[#This Row],[MC TOTAL (USD)]]/Tabla1[[#This Row],[INGRESO BRUTO (USD)]] -> 0.40291378 | N10: =+IFERROR(INDEX('Consolidados x MINERA'!$G$6:$G$11,MATCH(Tabla1[[#This Row],[UNIDAD MINERA]],'Consolidados x MINERA'!$A$6:$A$11,0))*Tabla1[[#This Row],[INGRESO BRUTO (USD)]]/SUMIFS(Tabla1[INGRESO BRUTO (USD)],Tabla1[UNIDAD MINERA],Tabla1[[#This Row],[UNIDAD MINERA]])/Tabla1[[#This Row],[VOLUMEN VENDIDO]],0) -> 0.0015852214 | O10: =+Tabla1[[#This Row],[COMPLEJIDAD X METAL UNITARIO]]*Tabla1[[#This Row],[VOLUMEN VENDIDO]] -> 6.9749743
A11: TX-1008 | B11: Q4-2025 | C11: Orcopampa | D11: Plata | E11: 4658 | F11: =_xlfn.XLOOKUP(D11,'DATOS CENTRALES'!$B$9:$B$25,'DATOS CENTRALES'!$D$9:$D$25,, ) -> oz | G11: =_xlfn.XLOOKUP(D11,'DATOS CENTRALES'!$B$9:$B$25,'DATOS CENTRALES'!$C$9:$C$25) -> 41.87 | H11: =+Tabla1[[#This Row],[VOLUMEN VENDIDO]]*Tabla1[[#This Row],[PRECIO UNITARIO (USD)]] -> 195030.46 | I11: =_xlfn.XLOOKUP(C11&"_"&D11, 'DATOS CENTRALES'!$F$9:$F$25, 'DATOS CENTRALES'!$E$9:$E$25, 0, 0) -> 25 | J11: =Tabla1[[#This Row],[CV UNITARIO]]*Tabla1[[#This Row],[VOLUMEN VENDIDO]] -> 116450 | K11: =+Tabla1[[#This Row],[PRECIO UNITARIO (USD)]]-Tabla1[[#This Row],[CV UNITARIO]] -> 16.87 | L11: =+Tabla1[[#This Row],[INGRESO BRUTO (USD)]]-Tabla1[[#This Row],[COSTO VARIABLE TOTAL (USD)]] -> 78580.46 | M11: =+Tabla1[[#This Row],[MC TOTAL (USD)]]/Tabla1[[#This Row],[INGRESO BRUTO (USD)]] -> 0.40291378 | N11: =+IFERROR(INDEX('Consolidados x MINERA'!$G$6:$G$11,MATCH(Tabla1[[#This Row],[UNIDAD MINERA]],'Consolidados x MINERA'!$A$6:$A$11,0))*Tabla1[[#This Row],[INGRESO BRUTO (USD)]]/SUMIFS(Tabla1[INGRESO BRUTO (USD)],Tabla1[UNIDAD MINERA],Tabla1[[#This Row],[UNIDAD MINERA]])/Tabla1[[#This Row],[VOLUMEN VENDIDO]],0) -> 0.0015852214 | O11: =+Tabla1[[#This Row],[COMPLEJIDAD X METAL UNITARIO]]*Tabla1[[#This Row],[VOLUMEN VENDIDO]] -> 7.3839614
A12: TX-1009 | B12: Q1-2025 | C12: Tambomayo | D12: Oro | E12: 3900 | F12: =_xlfn.XLOOKUP(D12,'DATOS CENTRALES'!$B$9:$B$25,'DATOS CENTRALES'!$D$9:$D$25,, ) -> oz | G12: =_xlfn.XLOOKUP(D12,'DATOS CENTRALES'!$B$9:$B$25,'DATOS CENTRALES'!$C$9:$C$25) -> 3547 | H12: =+Tabla1[[#This Row],[VOLUMEN VENDIDO]]*Tabla1[[#This Row],[PRECIO UNITARIO (USD)]] -> 13833300 | I12: =_xlfn.XLOOKUP(C12&"_"&D12, 'DATOS CENTRALES'!$F$9:$F$25, 'DATOS CENTRALES'!$E$9:$E$25, 0, 0) -> 2678 | J12: =Tabla1[[#This Row],[CV UNITARIO]]*Tabla1[[#This Row],[VOLUMEN VENDIDO]] -> 10444200 | K12: =+Tabla1[[#This Row],[PRECIO UNITARIO (USD)]]-Tabla1[[#This Row],[CV UNITARIO]] -> 869 | L12: =+Tabla1[[#This Row],[INGRESO BRUTO (USD)]]-Tabla1[[#This Row],[COSTO VARIABLE TOTAL (USD)]] -> 3389100 | M12: =+Tabla1[[#This Row],[MC TOTAL (USD)]]/Tabla1[[#This Row],[INGRESO BRUTO (USD)]] -> 0.24499577 | N12: =+IFERROR(INDEX('Consolidados x MINERA'!$G$6:$G$11,MATCH(Tabla1[[#This Row],[UNIDAD MINERA]],'Consolidados x MINERA'!$A$6:$A$11,0))*Tabla1[[#This Row],[INGRESO BRUTO (USD)]]/SUMIFS(Tabla1[INGRESO BRUTO (USD)],Tabla1[UNIDAD MINERA],Tabla1[[#This Row],[UNIDAD MINERA]])/Tabla1[[#This Row],[VOLUMEN VENDIDO]],0) -> 0.24416803 | O12: =+Tabla1[[#This Row],[COMPLEJIDAD X METAL UNITARIO]]*Tabla1[[#This Row],[VOLUMEN VENDIDO]] -> 952.25531
A13: TX-1010 | B13: Q2-2025 | C13: Tambomayo | D13: Oro | E13: 4100 | F13: =_xlfn.XLOOKUP(D13,'DATOS CENTRALES'!$B$9:$B$25,'DATOS CENTRALES'!$D$9:$D$25,, ) -> oz | G13: =_xlfn.XLOOKUP(D13,'DATOS CENTRALES'!$B$9:$B$25,'DATOS CENTRALES'!$C$9:$C$25) -> 3547 | H13: =+Tabla1[[#This Row],[VOLUMEN VENDIDO]]*Tabla1[[#This Row],[PRECIO UNITARIO (USD)]] -> 14542700 | I13: =_xlfn.XLOOKUP(C13&"_"&D13, 'DATOS CENTRALES'!$F$9:$F$25, 'DATOS CENTRALES'!$E$9:$E$25, 0, 0) -> 2678 | J13: =Tabla1[[#This Row],[CV UNITARIO]]*Tabla1[[#This Row],[VOLUMEN VENDIDO]] -> 10979800 | K13: =+Tabla1[[#This Row],[PRECIO UNITARIO (USD)]]-Tabla1[[#This Row],[CV UNITARIO]] -> 869 | L13: =+Tabla1[[#This Row],[INGRESO BRUTO (USD)]]-Tabla1[[#This Row],[COSTO VARIABLE TOTAL (USD)]] -> 3562900 | M13: =+Tabla1[[#This Row],[MC TOTAL (USD)]]/Tabla1[[#This Row],[INGRESO BRUTO (USD)]] -> 0.24499577 | N13: =+IFERROR(INDEX('Consolidados x MINERA'!$G$6:$G$11,MATCH(Tabla1[[#This Row],[UNIDAD MINERA]],'Consolidados x MINERA'!$A$6:$A$11,0))*Tabla1[[#This Row],[INGRESO BRUTO (USD)]]/SUMIFS(Tabla1[INGRESO BRUTO (USD)],Tabla1[UNIDAD MINERA],Tabla1[[#This Row],[UNIDAD MINERA]])/Tabla1[[#This Row],[VOLUMEN VENDIDO]],0) -> 0.24416803 | O13: =+Tabla1[[#This Row],[COMPLEJIDAD X METAL UNITARIO]]*Tabla1[[#This Row],[VOLUMEN VENDIDO]] -> 1001.0889
A14: TX-1011 | B14: Q3-2025 | C14: Tambomayo | D14: Oro | E14: 3800 | F14: =_xlfn.XLOOKUP(D14,'DATOS CENTRALES'!$B$9:$B$25,'DATOS CENTRALES'!$D$9:$D$25,, ) -> oz | G14: =_xlfn.XLOOKUP(D14,'DATOS CENTRALES'!$B$9:$B$25,'DATOS CENTRALES'!$C$9:$C$25) -> 3547 | H14: =+Tabla1[[#This Row],[VOLUMEN VENDIDO]]*Tabla1[[#This Row],[PRECIO UNITARIO (USD)]] -> 13478600 | I14: =_xlfn.XLOOKUP(C14&"_"&D14, 'DATOS CENTRALES'!$F$9:$F$25, 'DATOS CENTRALES'!$E$9:$E$25, 0, 0) -> 2678 | J14: =Tabla1[[#This Row],[CV UNITARIO]]*Tabla1[[#This Row],[VOLUMEN VENDIDO]] -> 10176400 | K14: =+Tabla1[[#This Row],[PRECIO UNITARIO (USD)]]-Tabla1[[#This Row],[CV UNITARIO]] -> 869 | L14: =+Tabla1[[#This Row],[INGRESO BRUTO (USD)]]-Tabla1[[#This Row],[COSTO VARIABLE TOTAL (USD)]] -> 3302200 | M14: =+Tabla1[[#This Row],[MC TOTAL (USD)]]/Tabla1[[#This Row],[INGRESO BRUTO (USD)]] -> 0.24499577 | N14: =+IFERROR(INDEX('Consolidados x MINERA'!$G$6:$G$11,MATCH(Tabla1[[#This Row],[UNIDAD MINERA]],'Consolidados x MINERA'!$A$6:$A$11,0))*Tabla1[[#This Row],[INGRESO BRUTO (USD)]]/SUMIFS(Tabla1[INGRESO BRUTO (USD)],Tabla1[UNIDAD MINERA],Tabla1[[#This Row],[UNIDAD MINERA]])/Tabla1[[#This Row],[VOLUMEN VENDIDO]],0) -> 0.24416803 | O14: =+Tabla1[[#This Row],[COMPLEJIDAD X METAL UNITARIO]]*Tabla1[[#This Row],[VOLUMEN VENDIDO]] -> 927.83851
A15: TX-1012 | B15: Q4-2025 | C15: Tambomayo | D15: Oro | E15: 4042 | F15: =_xlfn.XLOOKUP(D15,'DATOS CENTRALES'!$B$9:$B$25,'DATOS CENTRALES'!$D$9:$D$25,, ) -> oz | G15: =_xlfn.XLOOKUP(D15,'DATOS CENTRALES'!$B$9:$B$25,'DATOS CENTRALES'!$C$9:$C$25) -> 3547 | H15: =+Tabla1[[#This Row],[VOLUMEN VENDIDO]]*Tabla1[[#This Row],[PRECIO UNITARIO (USD)]] -> 14336974 | I15: =_xlfn.XLOOKUP(C15&"_"&D15, 'DATOS CENTRALES'!$F$9:$F$25, 'DATOS CENTRALES'!$E$9:$E$25, 0, 0) -> 2678 | J15: =Tabla1[[#This Row],[CV UNITARIO]]*Tabla1[[#This Row],[VOLUMEN VENDIDO]] -> 10824476 | K15: =+Tabla1[[#This Row],[PRECIO UNITARIO (USD)]]-Tabla1[[#This Row],[CV UNITARIO]] -> 869 | L15: =+Tabla1[[#This Row],[INGRESO BRUTO (USD)]]-Tabla1[[#This Row],[COSTO VARIABLE TOTAL (USD)]] -> 3512498 | M15: =+Tabla1[[#This Row],[MC TOTAL (USD)]]/Tabla1[[#This Row],[INGRESO BRUTO (USD)]] -> 0.24499577 | N15: =+IFERROR(INDEX('Consolidados x MINERA'!$G$6:$G$11,MATCH(Tabla1[[#This Row],[UNIDAD MINERA]],'Consolidados x MINERA'!$A$6:$A$11,0))*Tabla1[[#This Row],[INGRESO BRUTO (USD)]]/SUMIFS(Tabla1[INGRESO BRUTO (USD)],Tabla1[UNIDAD MINERA],Tabla1[[#This Row],[UNIDAD MINERA]])/Tabla1[[#This Row],[VOLUMEN VENDIDO]],0) -> 0.24416803 | O15: =+Tabla1[[#This Row],[COMPLEJIDAD X METAL UNITARIO]]*Tabla1[[#This Row],[VOLUMEN VENDIDO]] -> 986.92717
... A71: TX-1068 | B71: Q4-2025 | C71: Coimolache | D71: Plata | E71: 84401 | F71: =_xlfn.XLOOKUP(D71,'DATOS CENTRALES'!$B$9:$B$25,'DATOS CENTRALES'!$D$9:$D$25,, ) -> oz | G71: =_xlfn.XLOOKUP(D71,'DATOS CENTRALES'!$B$9:$B$25,'DATOS CENTRALES'!$C$9:$C$25) -> 41.87 | H71: =+Tabla1[[#This Row],[VOLUMEN VENDIDO]]*Tabla1[[#This Row],[PRECIO UNITARIO (USD)]] -> 3533869.9 | I71: =_xlfn.XLOOKUP(C71&"_"&D71, 'DATOS CENTRALES'!$F$9:$F$25, 'DATOS CENTRALES'!$E$9:$E$25, 0, 0) -> 30.97 | J71: =Tabla1[[#This Row],[CV UNITARIO]]*Tabla1[[#This Row],[VOLUMEN VENDIDO]] -> 2613899 | K71: =+Tabla1[[#This Row],[PRECIO UNITARIO (USD)]]-Tabla1[[#This Row],[CV UNITARIO]] -> 10.9 | L71: =+Tabla1[[#This Row],[INGRESO BRUTO (USD)]]-Tabla1[[#This Row],[COSTO VARIABLE TOTAL (USD)]] -> 919970.9 | M71: =+Tabla1[[#This Row],[MC TOTAL (USD)]]/Tabla1[[#This Row],[INGRESO BRUTO (USD)]] -> 0.26032959 | N71: =+IFERROR(INDEX('Consolidados x MINERA'!$G$6:$G$11,MATCH(Tabla1[[#This Row],[UNIDAD MINERA]],'Consolidados x MINERA'!$A$6:$A$11,0))*Tabla1[[#This Row],[INGRESO BRUTO (USD)]]/SUMIFS(Tabla1[INGRESO BRUTO (USD)],Tabla1[UNIDAD MINERA],Tabla1[[#This Row],[UNIDAD MINERA]])/Tabla1[[#This Row],[VOLUMEN VENDIDO]],0) -> 0.0014724901 | O71: =+Tabla1[[#This Row],[COMPLEJIDAD X METAL UNITARIO]]*Tabla1[[#This Row],[VOLUMEN VENDIDO]] -> 124.27964

Sheet Consolidados x MINERA
A1: ANÁLISIS DE COSTEO GERENCIAL
A3: MATRIZ DE COSTEO COMPLETO POR UNIDAD OPERATIVA SEGÚN UNIDAD OPERATIVA:
A5: UNIDAD MINERA | B5: INGRESOS CONSOL. (USD) | C5: COSTO VARIABLE CONSOL. (USD) | D5: MARGEN CONTRIB. (MC) (USD) | E5: % MC | F5: VOLUMEN MOLIDO (DMT) | G5: HORAS PLANTA (h) | H5: CF SEGÚN VOLUMEN (USD) | I5: CF SEGÚN HORAS (USD) | J5: VARIACIÓN CF (USD) | K5: UTILIDAD ABSORCIÓN (USD) | L5: UTILIDAD AJUSTADA (USD)
A6: Orcopampa | B6: =SUMIFS(DB_Ventas!$H$4:$H$71, DB_Ventas!$C$4:$C$71, A6) -> 1.9809535e+08 | C6: =SUMIFS(DB_Ventas!$J$4:$J$71, DB_Ventas!$C$4:$C$71, A6) -> 87244870 | D6: =Tabla2[[#This Row],[INGRESOS CONSOL. (USD)]]-Tabla2[[#This Row],[COSTO VARIABLE CONSOL. (USD)]] -> 1.1085048e+08 | E6: =IFERROR(D6/B6, 0) -> 0.55958144 | F6: 220951 | G6: 7500 | H6: =(Tabla2[[#This Row],[VOLUMEN MOLIDO (DMT)]]/$F$12)*'DATOS CENTRALES'!$B$5 -> 4212733.1 | I6: =(Tabla2[[#This Row],[HORAS PLANTA (h)]]/$G$12)*'DATOS CENTRALES'!$B$5 -> 45646008 | J6: =Tabla2[[#This Row],[CF SEGÚN HORAS (USD)]]-Tabla2[[#This Row],[CF SEGÚN VOLUMEN (USD)]] -> 41433275 | K6: =+Tabla2[[#This Row],[MARGEN CONTRIB. (MC) (USD)]]-Tabla2[[#This Row],[CF SEGÚN VOLUMEN (USD)]] -> 1.0663775e+08 | L6: =+Tabla2[[#This Row],[MARGEN CONTRIB. (MC) (USD)]]-Tabla2[[#This Row],[CF SEGÚN HORAS (USD)]] -> 65204475
A7: Tambomayo | B7: =SUMIFS(DB_Ventas!$H$4:$H$71, DB_Ventas!$C$4:$C$71, A7) -> 1.1621505e+08 | C7: =SUMIFS(DB_Ventas!$J$4:$J$71, DB_Ventas!$C$4:$C$71, A7) -> 80785444 | D7: =Tabla2[[#This Row],[INGRESOS CONSOL. (USD)]]-Tabla2[[#This Row],[COSTO VARIABLE CONSOL. (USD)]] -> 35429607 | E7: =IFERROR(D7/B7, 0) -> 0.30486247 | F7: 396958 | G7: 8000 | H7: =(Tabla2[[#This Row],[VOLUMEN MOLIDO (DMT)]]/$F$12)*'DATOS CENTRALES'!$B$5 -> 7568547.3 | I7: =(Tabla2[[#This Row],[HORAS PLANTA (h)]]/$G$12)*'DATOS CENTRALES'!$B$5 -> 48689076 | J7: =Tabla2[[#This Row],[CF SEGÚN HORAS (USD)]]-Tabla2[[#This Row],[CF SEGÚN VOLUMEN (USD)]] -> 41120528 | K7: =+Tabla2[[#This Row],[MARGEN CONTRIB. (MC) (USD)]]-Tabla2[[#This Row],[CF SEGÚN VOLUMEN (USD)]] -> 27861060 | L7: =+Tabla2[[#This Row],[MARGEN CONTRIB. (MC) (USD)]]-Tabla2[[#This Row],[CF SEGÚN HORAS (USD)]] -> -13259468
A8: Uchucchacua & Yumpag | B8: =SUMIFS(DB_Ventas!$H$4:$H$71, DB_Ventas!$C$4:$C$71, A8) -> 5.7116146e+08 | C8: =SUMIFS(DB_Ventas!$J$4:$J$71, DB_Ventas!$C$4:$C$71, A8) -> 2.0811432e+08 | D8: =Tabla2[[#This Row],[INGRESOS CONSOL. (USD)]]-Tabla2[[#This Row],[COSTO VARIABLE CONSOL. (USD)]] -> 3.6304714e+08 | E8: =IFERROR(D8/B8, 0) -> 0.63562962 | F8: 1010693 | G8: 8100 | H8: =(Tabla2[[#This Row],[VOLUMEN MOLIDO (DMT)]]/$F$12)*'DATOS CENTRALES'!$B$5 -> 19270245 | I8: =(Tabla2[[#This Row],[HORAS PLANTA (h)]]/$G$12)*'DATOS CENTRALES'!$B$5 -> 49297689 | J8: =Tabla2[[#This Row],[CF SEGÚN HORAS (USD)]]-Tabla2[[#This Row],[CF SEGÚN VOLUMEN (USD)]] -> 30027444 | K8: =+Tabla2[[#This Row],[MARGEN CONTRIB. (MC) (USD)]]-Tabla2[[#This Row],[CF SEGÚN VOLUMEN (USD)]] -> 3.437769e+08 | L8: =+Tabla2[[#This Row],[MARGEN CONTRIB. (MC) (USD)]]-Tabla2[[#This Row],[CF SEGÚN HORAS (USD)]] -> 3.1374945e+08
A9: El Brocal | B9: =SUMIFS(DB_Ventas!$H$4:$H$71, DB_Ventas!$C$4:$C$71, A9) -> 6.0207189e+08 | C9: =SUMIFS(DB_Ventas!$J$4:$J$71, DB_Ventas!$C$4:$C$71, A9) -> 3.7013758e+08 | D9: =Tabla2[[#This Row],[INGRESOS CONSOL. (USD)]]-Tabla2[[#This Row],[COSTO VARIABLE CONSOL. (USD)]] -> 2.319343e+08 | E9: =IFERROR(D9/B9, 0) -> 0.38522693 | F9: 4355560 | G9: 8300 | H9: =(Tabla2[[#This Row],[VOLUMEN MOLIDO (DMT)]]/$F$12)*'DATOS CENTRALES'!$B$5 -> 83044710 | I9: =(Tabla2[[#This Row],[HORAS PLANTA (h)]]/$G$12)*'DATOS CENTRALES'!$B$5 -> 50514916 | J9: =Tabla2[[#This Row],[CF SEGÚN HORAS (USD)]]-Tabla2[[#This Row],[CF SEGÚN VOLUMEN (USD)]] -> -32529794 | K9: =+Tabla2[[#This Row],[MARGEN CONTRIB. (MC) (USD)]]-Tabla2[[#This Row],[CF SEGÚN VOLUMEN (USD)]] -> 1.4888959e+08 | L9: =+Tabla2[[#This Row],[MARGEN CONTRIB. (MC) (USD)]]-Tabla2[[#This Row],[CF SEGÚN HORAS (USD)]] -> 1.8141939e+08
A10: Julcani | B10: =SUMIFS(DB_Ventas!$H$4:$H$71, DB_Ventas!$C$4:$C$71, A10) -> 92933796 | C10: =SUMIFS(DB_Ventas!$J$4:$J$71, DB_Ventas!$C$4:$C$71, A10) -> 58108394 | D10: =Tabla2[[#This Row],[INGRESOS CONSOL. (USD)]]-Tabla2[[#This Row],[COSTO VARIABLE CONSOL. (USD)]] -> 34825402 | E10: =IFERROR(D10/B10, 0) -> 0.37473345 | F10: 142191 | G10: 7200 | H10: =(Tabla2[[#This Row],[VOLUMEN MOLIDO (DMT)]]/$F$12)*'DATOS CENTRALES'!$B$5 -> 2711065.9 | I10: =(Tabla2[[#This Row],[HORAS PLANTA (h)]]/$G$12)*'DATOS CENTRALES'!$B$5 -> 43820168 | J10: =Tabla2[[#This Row],[CF SEGÚN HORAS (USD)]]-Tabla2[[#This Row],[CF SEGÚN VOLUMEN (USD)]] -> 41109102 | K10: =+Tabla2[[#This Row],[MARGEN CONTRIB. (MC) (USD)]]-Tabla2[[#This Row],[CF SEGÚN VOLUMEN (USD)]] -> 32114336 | L10: =+Tabla2[[#This Row],[MARGEN CONTRIB. (MC) (USD)]]-Tabla2[[#This Row],[CF SEGÚN HORAS (USD)]] -> -8994766.4
A11: Coimolache | B11: =SUMIFS(DB_Ventas!$H$4:$H$71, DB_Ventas!$C$4:$C$71, A11) -> 2.4169602e+08 | C11: =SUMIFS(DB_Ventas!$J$4:$J$71, DB_Ventas!$C$4:$C$71, A11) -> 1.0474435e+08 | D11: =Tabla2[[#This Row],[INGRESOS CONSOL. (USD)]]-Tabla2[[#This Row],[COSTO VARIABLE CONSOL. (USD)]] -> 1.3695167e+08 | E11: =IFERROR(D11/B11, 0) -> 0.56662776 | F11: 9067941 | G11: 8500 | H11: =(Tabla2[[#This Row],[VOLUMEN MOLIDO (DMT)]]/$F$12)*'DATOS CENTRALES'!$B$5 -> 1.728927e+08 | I11: =(Tabla2[[#This Row],[HORAS PLANTA (h)]]/$G$12)*'DATOS CENTRALES'!$B$5 -> 51732143 | J11: =Tabla2[[#This Row],[CF SEGÚN HORAS (USD)]]-Tabla2[[#This Row],[CF SEGÚN VOLUMEN (USD)]] -> -1.2116056e+08 | K11: =+Tabla2[[#This Row],[MARGEN CONTRIB. (MC) (USD)]]-Tabla2[[#This Row],[CF SEGÚN VOLUMEN (USD)]] -> -35941025 | L11: =+Tabla2[[#This Row],[MARGEN CONTRIB. (MC) (USD)]]-Tabla2[[#This Row],[CF SEGÚN HORAS (USD)]] -> 85219532
A12: TOTAL CONSOLIDADO | B12: =SUM(B6:B11) -> 1.8221736e+09 | C12: =SUM(C6:C11) -> 9.0913496e+08 | D12: =Tabla2[[#This Row],[INGRESOS CONSOL. (USD)]]-Tabla2[[#This Row],[COSTO VARIABLE CONSOL. (USD)]] -> 9.1303861e+08 | E12: =+D12/B12 -> 0.50107115 | F12: =SUM(F6:F11) -> 15194294 | G12: =SUM(G6:G11) -> 47600 | H12: =SUM(H6:H11) -> 289700000 | I12: =SUM(I6:I11) -> 289700000 | J12: =SUM(J6:J11) -> 0 | K12: =SUM(K6:K11) -> 6.2333861e+08 | L12: =SUM(L6:L11) -> 6.2333861e+08

Sheet TABLA DINAMICA METALES
B3: Etiquetas de fila | C3: Suma de INGRESO BRUTO (USD) | D3: Suma de VOLUMEN VENDIDO | E3: porcentaING | F3: distribuccfcomuning | G3: porcentacompl | H3: distribuccfcomun | I3: Suma de PRECIO UNITARIO (USD) | J3: Suma de CV UNITARIO | K3: Suma de COSTO VARIABLE TOTAL (USD) | L3: Suma de MC TOTAL (USD) | M3: Suma de MC TOTAL (USD)2
B4: Cobre | C4: 526239963 | D4: 52253 | E4: 0.28879793 | F4: 83664762 | G4: 0.15713732 | H4: 45522682 | I4: 80568 | J4: 51744 | K4: 336271221 | L4: 189968742 | M4: 0.20806211
B5: Oro | C5: 512087484 | D5: 144372 | E5: 0.28103112 | F5: 81414716 | G5: 0.45658157 | H5: 1.3227168e+08 | I5: 56752 | J5: 31556 | K5: 242590075 | L5: 269497409 | M5: 0.2951654
B6: Plata | C6: 6.6409999e+08 | D6: 15860998 | E6: 0.36445485 | F6: 1.0558257e+08 | G6: 0.33379453 | H6: 96700274 | I6: 1004.88 | J6: 575.68 | K6: 2.8278284e+08 | L6: 3.8131715e+08 | M6: 0.41763529
B7: Plomo | C7: 37213256 | D7: 19463 | E7: 0.020422454 | F7: 5916384.9 | G7: 0.018815653 | H7: 5450894.6 | I7: 22944 | J7: 12328 | K7: 13607350 | L7: 23605906 | M7: 0.025854225
B8: Zinc | C8: 82532880 | D8: 29020 | E8: 0.045293643 | F8: 13121569 | G8: 0.033670927 | H8: 9754467.4 | I8: 22752 | J8: 10744 | K8: 33883474 | L8: 48649406 | M8: 0.053282967
B9: Total general | C9: 1.8221736e+09 | D9: 16106106 | E9: 1 | F9: 289700000 | G9: 1 | H9: 289700000 | I9: 184020.88 | J9: 106947.68 | K9: 9.0913496e+08 | L9: 9.1303861e+08 | M9: 1
D11: NOTA GERENCIAL: Se repartió el CF común con unidades comparables: (1) a cada mina por sus horas de planta y (2) dentro de cada mina a sus metales por ingresos; así no se suman onzas con toneladas. La Plata asume USD 96.7 M de CF (antes 251.6 M) y gana USD 284.62 M; el Oro asume 132.27 M y gana 137.23 M; el Cobre gana 144.45 M. Subsidio cruzado = Base 2 − Base 1: (+) el metal era subsidiado por los demás; (−) subsidiaba a otros.

Sheet Consolidado x metales
A1: REPORTE RESUMIDO GERENCIAL - METALES
A3: METAL | B3: INGRESOS TOTALES (USD) | C3: COSTO VARIABLE TOTAL (USD) | D3: MARGEN DE CONTRIBUCIÓN (USD) | E3: % MC | F3: Complejidad | G3: % INGRESOS | H3: BASE 1: CF POR INGRESOS (USD) | I3: UTILIDAD ABSORCIÓN | J3: % COMPLEJIDAD PLANTA | K3: BASE 2: CF POR COMPLEJIDAD (USD) | L3: UTILIDAD AJUSTADA | M3: SUBSIDIO CRUZADO / VAR. (USD)
A4: Oro | B4: =SUMIFS(DB_Ventas!$H$4:$H$71, DB_Ventas!$D$4:$D$71, A4) -> 512087484 | C4: =SUMIFS(DB_Ventas!$J$4:$J$71, DB_Ventas!$D$4:$D$71, A4) -> 242590075 | D4: =Tablametales[[#This Row],[INGRESOS TOTALES (USD)]]-Tablametales[[#This Row],[COSTO VARIABLE TOTAL (USD)]] -> 269497409 | E4: =+Tablametales[[#This Row],[MARGEN DE CONTRIBUCIÓN (USD)]]/Tablametales[[#This Row],[INGRESOS TOTALES (USD)]] -> 0.5262722 | F4: =SUMIFS(Tabla1[COMPLEJIDAD X METAL total],Tabla1[METAL], Tablametales[[#This Row],[METAL]]) -> 21733.283 | G4: =B4/$B$9 -> 0.28103112 | H4: =G4*'DATOS CENTRALES'!$B$5 -> 81414716 | I4: =+Tablametales[[#This Row],[MARGEN DE CONTRIBUCIÓN (USD)]]-Tabla4[[#This Row],[BASE 1: CF POR INGRESOS (USD)]] -> 1.8808269e+08 | J4: =+Tablametales[[#This Row],[Complejidad]]/$F$9 -> 0.45658157 | K4: =J4*'DATOS CENTRALES'!$B$5 -> 1.3227168e+08 | L4: =Tablametales[[#This Row],[MARGEN DE CONTRIBUCIÓN (USD)]]-Tabla4[[#This Row],[BASE 2: CF POR COMPLEJIDAD (USD)]] -> 1.3722573e+08 | M4: =Tabla4[[#This Row],[BASE 2: CF POR COMPLEJIDAD (USD)]]-Tabla4[[#This Row],[BASE 1: CF POR INGRESOS (USD)]] -> 50856966
A5: Plata | B5: =SUMIFS(DB_Ventas!$H$4:$H$71, DB_Ventas!$D$4:$D$71, A5) -> 6.6409999e+08 | C5: =SUMIFS(DB_Ventas!$J$4:$J$71, DB_Ventas!$D$4:$D$71, A5) -> 2.8278284e+08 | D5: =Tablametales[[#This Row],[INGRESOS TOTALES (USD)]]-Tablametales[[#This Row],[COSTO VARIABLE TOTAL (USD)]] -> 3.8131715e+08 | E5: =+Tablametales[[#This Row],[MARGEN DE CONTRIBUCIÓN (USD)]]/Tablametales[[#This Row],[INGRESOS TOTALES (USD)]] -> 0.57418635 | F5: =SUMIFS(Tabla1[COMPLEJIDAD X METAL total],Tabla1[METAL], Tablametales[[#This Row],[METAL]]) -> 15888.619 | G5: =B5/$B$9 -> 0.36445485 | H5: =G5*'DATOS CENTRALES'!$B$5 -> 1.0558257e+08 | I5: =+Tablametales[[#This Row],[MARGEN DE CONTRIBUCIÓN (USD)]]-Tabla4[[#This Row],[BASE 1: CF POR INGRESOS (USD)]] -> 2.7573458e+08 | J5: =+Tablametales[[#This Row],[Complejidad]]/$F$9 -> 0.33379453 | K5: =J5*'DATOS CENTRALES'!$B$5 -> 96700274 | L5: =+Tablametales[[#This Row],[MARGEN DE CONTRIBUCIÓN (USD)]]-Tabla4[[#This Row],[BASE 2: CF POR COMPLEJIDAD (USD)]] -> 2.8461687e+08 | M5: =+Tabla4[[#This Row],[BASE 2: CF POR COMPLEJIDAD (USD)]]-Tabla4[[#This Row],[BASE 1: CF POR INGRESOS (USD)]] -> -8882294.2
A6: Cobre | B6: =SUMIFS(DB_Ventas!$H$4:$H$71, DB_Ventas!$D$4:$D$71, A6) -> 526239963 | C6: =SUMIFS(DB_Ventas!$J$4:$J$71, DB_Ventas!$D$4:$D$71, A6) -> 336271221 | D6: =Tablametales[[#This Row],[INGRESOS TOTALES (USD)]]-Tablametales[[#This Row],[COSTO VARIABLE TOTAL (USD)]] -> 189968742 | E6: =+Tablametales[[#This Row],[MARGEN DE CONTRIBUCIÓN (USD)]]/Tablametales[[#This Row],[INGRESOS TOTALES (USD)]] -> 0.36099262 | F6: =SUMIFS(Tabla1[COMPLEJIDAD X METAL total],Tabla1[METAL], Tablametales[[#This Row],[METAL]]) -> 7479.7364 | G6: =B6/$B$9 -> 0.28879793 | H6: =G6*'DATOS CENTRALES'!$B$5 -> 83664762 | I6: =+Tablametales[[#This Row],[MARGEN DE CONTRIBUCIÓN (USD)]]-Tabla4[[#This Row],[BASE 1: CF POR INGRESOS (USD)]] -> 1.0630398e+08 | J6: =+Tablametales[[#This Row],[Complejidad]]/$F$9 -> 0.15713732 | K6: =J6*'DATOS CENTRALES'!$B$5 -> 45522682 | L6: =+Tablametales[[#This Row],[MARGEN DE CONTRIBUCIÓN (USD)]]-Tabla4[[#This Row],[BASE 2: CF POR COMPLEJIDAD (USD)]] -> 1.4444606e+08 | M6: =+Tabla4[[#This Row],[BASE 2: CF POR COMPLEJIDAD (USD)]]-Tabla4[[#This Row],[BASE 1: CF POR INGRESOS (USD)]] -> -38142080
A7: Plomo | B7: =SUMIFS(DB_Ventas!$H$4:$H$71, DB_Ventas!$D$4:$D$71, A7) -> 37213256 | C7: =SUMIFS(DB_Ventas!$J$4:$J$71, DB_Ventas!$D$4:$D$71, A7) -> 13607350 | D7: =Tablametales[[#This Row],[INGRESOS TOTALES (USD)]]-Tablametales[[#This Row],[COSTO VARIABLE TOTAL (USD)]] -> 23605906 | E7: =+Tablametales[[#This Row],[MARGEN DE CONTRIBUCIÓN (USD)]]/Tablametales[[#This Row],[INGRESOS TOTALES (USD)]] -> 0.63434132 | F7: =SUMIFS(Tabla1[COMPLEJIDAD X METAL total],Tabla1[METAL], Tablametales[[#This Row],[METAL]]) -> 895.62507 | G7: =B7/$B$9 -> 0.020422454 | H7: =G7*'DATOS CENTRALES'!$B$5 -> 5916384.9 | I7: =+Tablametales[[#This Row],[MARGEN DE CONTRIBUCIÓN (USD)]]-Tabla4[[#This Row],[BASE 1: CF POR INGRESOS (USD)]] -> 17689521 | J7: =+Tablametales[[#This Row],[Complejidad]]/$F$9 -> 0.018815653 | K7: =J7*'DATOS CENTRALES'!$B$5 -> 5450894.6 | L7: =+Tablametales[[#This Row],[MARGEN DE CONTRIBUCIÓN (USD)]]-Tabla4[[#This Row],[BASE 2: CF POR COMPLEJIDAD (USD)]] -> 18155011 | M7: =+Tabla4[[#This Row],[BASE 2: CF POR COMPLEJIDAD (USD)]]-Tabla4[[#This Row],[BASE 1: CF POR INGRESOS (USD)]] -> -465490.33
A8: Zinc | B8: =SUMIFS(DB_Ventas!$H$4:$H$71, DB_Ventas!$D$4:$D$71, A8) -> 82532880 | C8: =SUMIFS(DB_Ventas!$J$4:$J$71, DB_Ventas!$D$4:$D$71, A8) -> 33883474 | D8: =Tablametales[[#This Row],[INGRESOS TOTALES (USD)]]-Tablametales[[#This Row],[COSTO VARIABLE TOTAL (USD)]] -> 48649406 | E8: =+Tablametales[[#This Row],[MARGEN DE CONTRIBUCIÓN (USD)]]/Tablametales[[#This Row],[INGRESOS TOTALES (USD)]] -> 0.58945485 | F8: =SUMIFS(Tabla1[COMPLEJIDAD X METAL total],Tabla1[METAL], Tablametales[[#This Row],[METAL]]) -> 1602.7361 | G8: =B8/$B$9 -> 0.045293643 | H8: =G8*'DATOS CENTRALES'!$B$5 -> 13121569 | I8: =+Tablametales[[#This Row],[MARGEN DE CONTRIBUCIÓN (USD)]]-Tabla4[[#This Row],[BASE 1: CF POR INGRESOS (USD)]] -> 35527837 | J8: =+Tablametales[[#This Row],[Complejidad]]/$F$9 -> 0.033670927 | K8: =J8*'DATOS CENTRALES'!$B$5 -> 9754467.4 | L8: =+Tablametales[[#This Row],[MARGEN DE CONTRIBUCIÓN (USD)]]-Tabla4[[#This Row],[BASE 2: CF POR COMPLEJIDAD (USD)]] -> 38894939 | M8: =+Tabla4[[#This Row],[BASE 2: CF POR COMPLEJIDAD (USD)]]-Tabla4[[#This Row],[BASE 1: CF POR INGRESOS (USD)]] -> -3367101.1
A9: TOTAL CONSOLIDADO | B9: =SUM(B4:B8) -> 1.8221736e+09 | C9: =SUM(C4:C8) -> 9.0913496e+08 | D9: =Tablametales[[#This Row],[INGRESOS TOTALES (USD)]]-Tablametales[[#This Row],[COSTO VARIABLE TOTAL (USD)]] -> 9.1303861e+08 | F9: =SUM(F4:F8) -> 47600 | G9: =SUM(G4:G8) -> 1 | H9: =SUM(H4:H8) -> 2.897e+08 | I9: =SUM(I4:I8) -> 6.2333861e+08 | J9: =SUM(J4:J8) -> 1 | K9: =SUM(K4:K8) -> 2.897e+08 | L9: =SUM(L4:L8) -> 6.2333861e+08 | M9: =SUM(M4:M8) -> 4.3772161e-08
H12: VOLUMEN VENDIDO POR METALES | K12: NOTA GERENCIAL: Se repartió el CF común con unidades comparables: (1) a cada mina por sus horas de planta y (2) dentro de cada mina a sus metales por ingresos; así no se suman onzas con toneladas. La Plata asume USD 96.7 M de CF (antes 251.6 M) y gana USD 284.62 M; el Oro asume 132.27 M y gana 137.23 M; el Cobre gana 144.45 M. Subsidio cruzado = Base 2 − Base 1: (+) el metal era subsidiado por los demás; (−) subsidiaba a otros.
H13: =+SUMIF(Tabla1[METAL],'Consolidado x metales'!A4,Tabla1[VOLUMEN VENDIDO]) -> 144372
A14: Etiquetas de fila | B14: Suma de INGRESOS TOTALES (USD) | C14: Suma de MARGEN DE CONTRIBUCIÓN (USD) | D14: Suma de MARGEN DE CONTRIBUCIÓN (USD)2 | E14: Suma de BASE 2: CF POR COMPLEJIDAD (USD) | H14: =+SUMIF(Tabla1[METAL],'Consolidado x metales'!A5,Tabla1[VOLUMEN VENDIDO]) -> 15860998
A15: Cobre | B15: 526239963 | C15: 189968742 | D15: 0.20806211 | E15: 45522682 | H15: =+SUMIF(Tabla1[METAL],'Consolidado x metales'!A6,Tabla1[VOLUMEN VENDIDO]) -> 52253
A16: Oro | B16: 512087484 | C16: 269497409 | D16: 0.2951654 | E16: 1.3227168e+08 | H16: =+SUMIF(Tabla1[METAL],'Consolidado x metales'!A7,Tabla1[VOLUMEN VENDIDO]) -> 19463
A17: Plata | B17: 6.6409999e+08 | C17: 3.8131715e+08 | D17: 0.41763529 | E17: 96700274 | H17: =+SUMIF(Tabla1[METAL],'Consolidado x metales'!A8,Tabla1[VOLUMEN VENDIDO]) -> 29020
A18: Plomo | B18: 37213256 | C18: 23605906 | D18: 0.025854225 | E18: 5450894.6 | H18: =SUM(H13:H17) -> 16106106
A19: Zinc | B19: 82532880 | C19: 48649406 | D19: 0.053282967 | E19: 9754467.4
A20: Total general | B20: 1.8221736e+09 | C20: 9.1303861e+08 | D20: 1 | E20: 289700000

Sheet ESCENARIO DE ORO
A1: ADMINISTRADOR DE ESCENARIOS · MODELO BÁSICO
A2: Seleccione Base, Pesimista u Optimista en B3; el Estado de Resultados se recalcula.
A3: Escenario activo | B3: Pesimista
A5: SUPUESTOS POR ESCENARIO
A6: Escenario | B6: Precio x onza | C6: Volumen x onza | D6: Cv oro x onza | E6: Gastos fijos $ | F6: Gasto financiero $ | G6: Tasa impuesto
A7: Base | B7: 3547 | C7: 144372 | D7: 1560 | E7: =+'Consolidado x metales'!K4 -> 1.3227168e+08 | F7: 2340000 | G7: 0.295 | I7: ESCENARIO PESIMISTA | J7: Caída en Precios (-20.0%): Corrección cíclica en las cotizaciones LBMA/LME impulsada por altas tasas de interés globales y fortaleza del dólar.
A8: Pesimista | B8: 2837.6 | C8: 122716.2 | D8: =+D7+(B47*D7) -> 1747.2 | E8: =+E7+(E7*B48) -> 1.4285342e+08 | F8: =+F7+(F7*B49) -> 2691000 | G8: 0.295 | J8: Aumento de Costo CAS (+12.0%): Inflación en insumos químicos clave (cianuro de sodio, cal, reactivos de flotación) y mayor costo de fletes y energía eléctrica industrial.
A9: Optimista | B9: 4256.4 | C9: 173246.4 | D9: 1435.2 | E9: =+E7+(E7*C48) -> 1.256581e+08 | F9: =+F7+(F7*C49) -> 2574000 | G9: 0.295 | J9: Caída en Volumen (-12.0%):
I10: ESCENARIO OPTIMISTA | J10: Alza en Precios (+20.0%): Cotizaciones récord del Oro (> $4,000/oz) y Plata (> $50/oz) como activos refugio, y superciclo del Cobre por electrificación global.
A11: ENTRADAS ACTIVAS | E11: ESTADO DE RESULTADOS | J11: Aumento en Volumen (+20.0%)
A12: Variable | B12: Valor | C12: ValorEspejo | E12: Concepto | F12: Importe ($) | G12: Porcenatje | J12: Disminución de Costo CAS (-8.0%): Economías de escala y dilución de costos fijos operacionales gracias a la mayor escala de procesamiento.
A13: Precio de venta (S/ONZA) | B13: =+_xlfn.XLOOKUP(B3,A7:A9,B7:B9) -> 2837.6 | C13: =_xlfn.XLOOKUP($B$3,$A$7:$A$9,$B$7:$B$9) -> 2837.6 | E13: Ventas | F13: =B13*B14 -> 3.4821949e+08 | G13: =+F13/F13 -> 1
A14: Volumen (ONZA) | B14: =+_xlfn.XLOOKUP($B$3,$A$7:$A$9,C7:C9) -> 122716.2 | C14: =_xlfn.XLOOKUP($B$3,$A$7:$A$9,$C$7:$C$9) -> 122716.2 | E14: Costo de oro | F14: =B14*B15 -> 2.1440974e+08 | G14: =+F14/F13 -> 0.6157316
A15: Costo del oro (S//onza) | B15: =+_xlfn.XLOOKUP($B$3,$A$7:$A$9,D7:D9) -> 1747.2 | C15: =_xlfn.XLOOKUP($B$3,$A$7:$A$9,$D$7:$D$9) -> 1747.2 | E15: Costo de ventas | F15: =F14 -> 2.1440974e+08 | G15: =+F15/F13 -> 0.6157316
A16: Gastos operativos fijos (S/) | B16: =+_xlfn.XLOOKUP($B$3,$A$7:$A$9,E7:E9) -> 1.4285342e+08 | C16: =_xlfn.XLOOKUP($B$3,$A$7:$A$9,$E$7:$E$9) -> 1.4285342e+08 | E16: Utilidad bruta | F16: =F13-F15 -> 1.3380974e+08 | G16: =+F16/F13 -> 0.3842684 | I16: 3547 | J16: 144372 | K16: 1560 | L16: 1.3227168e+08 | M16: 2340000 | N16: 0.295
A17: Gastos financieros (S/) | B17: =+_xlfn.XLOOKUP($B$3,$A$7:$A$9,F7:F9) -> 2691000 | C17: =_xlfn.XLOOKUP($B$3,$A$7:$A$9,$F$7:$F$9) -> 2691000 | E17: Gastos operativos | F17: =B16 -> 1.4285342e+08 | G17: =+F17/F13 -> 0.41023958 | I17: 2837.6 | J17: 122716.2 | K17: 1747.2 | L17: 1.4285342e+08 | M17: 2691000 | N17: 0.295
A18: Tasa de impuesto | B18: 0.295 | C18: =_xlfn.XLOOKUP($B$3,$A$7:$A$9,$G$7:$G$9) -> 0.295 | E18: Utilidad operativa | F18: =F16-F17 -> -9043672.1 | G18: =+F18/F13 -> -0.025971183 | I18: 4256.4 | J18: 173246.4 | K18: 1435.2 | L18: 1.256581e+08 | M18: 2574000 | N18: 0.295
E19: Gastos financieros | F19: =B17 -> 2691000 | G19: =+F19/F13 -> 0.0077278845
E20: Utilidad antes de impuesto | F20: =F18-F19 -> -11734672 | G20: =+F20/F13 -> -0.033699068
E21: Impuesto académico | F21: =+F20*B18 -> -3461728.3 | G21: =+F21/F13 -> -0.0099412249
E22: Utilidad neta | F22: =F20-F21 -> -8272943.8 | G22: =+F22/F13 -> -0.023757843
D25: MATRIZ: VARIACIÓN DE PRECIO DEL ORO × VARIACIÓN CV DEL ORO
E26: -0.3 | F26: -0.2 | G26: -0.1 | H26: 0 | I26: 0.1 | J26: 0.2 | K26: 0.3
D27: =+F20 -> -11734672 | E27: 2482.9 | F27: 2837.6 | G27: 3192.3 | H27: 3547 | I27: 3901.7 | J27: 4256.4 | K27: 4611.1
C28: -0.2 | D28: 1248 | E28: 5997818.8 | F28: 49525255 | G28: 93052691 | H28: 1.3658013e+08 | I28: 1.8010756e+08 | J28: 2.23635e+08 | K28: 2.6716244e+08
C29: -0.1 | D29: 1404 | E29: -13145908 | F29: 30381528 | G29: 73908964 | H29: 1.174364e+08 | I29: 1.6096384e+08 | J29: 2.0449127e+08 | K29: 2.4801871e+08
C30: 0 | D30: 1560 | E30: -32289636 | F30: 11237801 | G30: 54765237 | H30: 98292673 | I30: 1.4182011e+08 | J30: 1.8534755e+08 | K30: 2.2887498e+08
C31: 0.1 | D31: 1716 | E31: -51433363 | F31: -7905926.7 | G31: 35621509 | H31: 79148946 | I31: 1.2267638e+08 | J31: 1.6620382e+08 | K31: 2.0973125e+08
C32: 0.2 | D32: 1872 | E32: -70577090 | F32: -27049654 | G32: 16477782 | H32: 60005218 | I32: 1.0353265e+08 | J32: 1.4706009e+08 | K32: 1.9058753e+08
A43: PARÁMETROS DE VARIACIÓN
A44: VARIABLE | B44: PESIMISTA | C44: OPTIMISTA | D44: FUNDAMENTO CUANTITATIVO (de dónde sale el %)
A45: Precio realizado | B45: -0.2 | C45: 0.2 | D45: Un tercio de la brecha entre el precio realizado (B9) y el precio de equilibrio (B17). Mientras más colchón tiene el metal, mayor es la caída que el escenario le exige resistir.
A46: Volumen vendido | B46: -0.15 | C46: 0.2 | D46: Paralización (o ampliación) de un trimestre en la unidad minera que concentra el volumen del metal: 25% x participación dominante (C28).
A47: Costo variable unitario | B47: 0.12 | C47: -0.08 | D47: Mitad de la brecha entre el CVu de la mina más cara (o más barata) del metal y el CVu promedio ponderado (B10). Es la brecha de eficiencia realmente observada en DATOS CENTRALES.
A48: Costos fijos asignados | B48: 0.08 | C48: ='[1]DATOS CENTRALES'!$B$32 -> -0.05 | D48: Inflación / eficiencia de la estructura fija corporativa (DATOS CENTRALES B31-B32).
A49: Gastos financieros | B49: 0.15 | C49: 0.1 | D49: Encarecimiento o refinanciamiento del servicio de deuda (DATOS CENTRALES B33-B34).

Sheet Resumen del escenario
B2: Resumen del escenario
D3: Valores actuales: | E3: BASE | F3: OPTIMISTA | G3: PESIMISTA
E4: Creado por CICELY GUILLEN el 22/09/2026 | F4: Creado por CICELY GUILLEN el 22/09/2026 | G4: Creado por CICELY GUILLEN el 22/09/2026
B5: Celdas cambiantes:
C6: $B$13 | D6: 2837.6 | E6: 3547 | F6: 4256.4 | G6: 2837.6
C7: $B$14 | D7: 122716.2 | E7: 144372 | F7: 173246.4 | G7: 122716.2
C8: $B$15 | D8: 1747.2 | E8: 1560 | F8: 1435.2 | G8: 1747.2
C9: $B$16 | D9: 1.4285342e+08 | E9: 1.3227168e+08 | F9: 1.256581e+08 | G9: 1.4285342e+08
C10: $B$17 | D10: 2691000 | E10: 2340000 | F10: 2574000 | G10: 2691000
C11: $B$18 | D11: 0.295 | E11: 0.295 | F11: 0.295 | G11: 0.295
B12: Celdas de resultado:
C13: $F$20 | D13: -11734672 | E13: 1.5225548e+08 | F13: 3.6053065e+08 | G13: -11734672
B14: Notas: La columna de valores actuales representa los valores de las celdas cambiantes
B15: en el momento en que se creó el Informe resumen de escenario. Las celdas cambiantes de
B16: cada escenario se muestran en gris.

Sheet Tabla dinámica del escenario
A1: $B$13:$B$18 por | B1: (Todas)
A3: ESCENARIOS | B3: UTILIDAD ANTES DE IMPUESTOS
A4: BASE | B4: 1.5225548e+08
A5: OPTIMISTA | B5: 3.6053065e+08
A6: PESIMISTA | B6: -11734672
A17: TABLERO DE SENSIBILIDAD
A18: ESCENARIO | C18: VENTAS (S/) | E18: UTILIDAD NETA (S/) | G18: MARGEN NETO
A19: =+'ESCENARIO DE ORO'!B3 -> Pesimista | C19: =+'ESCENARIO DE ORO'!F13 -> 3.4821949e+08 | E19: =+'ESCENARIO DE ORO'!F22 -> -8272943.8 | G19: =IFERROR('ESCENARIO DE ORO'!F22/'ESCENARIO DE ORO'!F13,0) -> -0.023757843
A22: HISTORIA EN BREVE
A23: ="En el escenario "&A19&", las ventas son $ "&ROUND(C19/1000000,2)&" y la utilidad neta es $ "&ROUND(E19/1000000,2)&". El costo del oro/onz representa "&ROUND(G19*100,2)&"% de las ventas. " -> En el escenario Pesimista, las ventas son $ 348.22 y la utilidad neta es $ -8.27. El costo del oro/onz representa -2.38% de las ventas.

Sheet ANALISIS CVU
A1: ANÁLISIS COSTO-VOLUMEN-UTILIDAD Y PUNTO DE EQUILIBRIO CORPORATIVO
A2: METAL - ORO
A3: CÁLCULO DEL PUNTO DE EQUILIBRIO CORPORATIVO (PDE)
A4: Ingresos Brutos Totales (Ventas Base FY25) | B4: =+Tablametales[[#This Row],[INGRESOS TOTALES (USD)]] -> 512087484 | C4: Es un motor gigante, muy rentable y sumamente estable.
A5: (-) Costo Variable CAS Total | B5: =+'Consolidado x metales'!C4 -> 242590075
A6: Margen de Contribución Total (MC) | B6: =B4-B5 -> 269497409
A7: % Margen de Contribución Global (%MC) | B7: =B6/B4 -> 0.5262722
A8: Costos Fijos Comunes Corporativos (CF) | B8: =+'ESCENARIO DE ORO'!E7 -> 1.3227168e+08
A9: PUNTO DE EQUILIBRIO EN VENTAS (PDE USD) | B9: =B8/B7 -> 2.5133701e+08
A10: MARGEN DE SEGURIDAD (EN USD) | B10: =B4-B9 -> 2.6075047e+08
A11: MARGEN DE SEGURIDAD (EN %) | B11: =B10/B4 -> 0.50919127
A13: ANÁLISIS:
A14: =+"El oro vende USD "&ROUND(B4/1000000,2)&" millones y solo necesita USD "&ROUND(B9/1000000,2)&" para cubrir sus costos fijos de USD "&ROUND(B8/1000000,2)&" millones y no perder dinero. El oro tiene un colchón de USD "&ROUND(B10/1000000,2)&" y sus ventas tendrían que caer más del "&ROUND(B11*100,2)&"% antes de que la linea empiece a generar perdidas." -> El oro vende USD 512.09 millones y solo necesita USD 251.34 para cubrir sus costos fijos de USD 132.27 millones y no perder dinero. El oro tiene un colchón de USD 260.75 y sus ventas tendrían que caer más del 50.92% antes de que la linea empiece a generar perdidas.
A17: ANÁLISIS COSTO-VOLUMEN-UTILIDAD Y PUNTO DE EQUILIBRIO CORPORATIVO
A18: METAL - PLATA
A19: CÁLCULO DEL PUNTO DE EQUILIBRIO CORPORATIVO (PDE)
A20: Ingresos Brutos Totales (Ventas Base FY25) | B20: =+'Consolidado x metales'!B5 -> 6.6409999e+08 | C20: Es el mayor aportador de margen de contribución de la empresa y tiene un colchón de seguridad amplio.
A21: (-) Costo Variable CAS Total | B21: =+'Consolidado x metales'!C5 -> 2.8278284e+08
A22: Margen de Contribución Total (MC) | B22: =B20-B21 -> 3.8131715e+08
A23: % Margen de Contribución Global (%MC) | B23: =B22/B20 -> 0.57418635
A24: Costos Fijos Comunes Corporativos (CF) | B24: =+'Consolidado x metales'!K5 -> 96700274
A25: PUNTO DE EQUILIBRIO EN VENTAS (PDE USD) | B25: =B24/B23 -> 1.684127e+08
A26: MARGEN DE SEGURIDAD (EN USD) | B26: =B20-B25 -> 4.9568729e+08
A27: MARGEN DE SEGURIDAD (EN %) | B27: =B26/B20 -> 0.7464046
A29: ANÁLISIS:
A30: =+"La plata vende USD "&ROUND(B20/1000000,2)&" millones y solo necesita USD "&ROUND(B25/1000000,2)&" para cubrir sus costos fijos de USD "&ROUND(B24/1000000,2)&" millones y no perder dinero. La plata tiene un colchón de USD "&ROUND(B26/1000000,2)&" y sus ventas tendrían que caer más del "&ROUND(B27*100,2)&"% antes de que la linea empiece a generar perdidas." -> La plata vende USD 664.1 millones y solo necesita USD 168.41 para cubrir sus costos fijos de USD 96.7 millones y no perder dinero. La plata tiene un colchón de USD 495.69 y sus ventas tendrían que caer más del 74.64% antes de que la linea empiece a generar perdidas.
A33: ANÁLISIS COSTO-VOLUMEN-UTILIDAD Y PUNTO DE EQUILIBRIO CORPORATIVO
A34: METAL - COBRE
A35: CÁLCULO DEL PUNTO DE EQUILIBRIO CORPORATIVO (PDE)
A36: Ingresos Brutos Totales (Ventas Base FY25) | B36: =+'Consolidado x metales'!B6 -> 526239963 | C36: Necesita vender más volumen que los demás porque procesarlo en la mina cuesta más caro
A37: (-) Costo Variable CAS Total | B37: =+'Consolidado x metales'!C6 -> 336271221
A38: Margen de Contribución Total (MC) | B38: =B36-B37 -> 189968742
A39: % Margen de Contribución Global (%MC) | B39: =B38/B36 -> 0.36099262
A40: Costos Fijos Comunes Corporativos (CF) | B40: =+'Consolidado x metales'!K6 -> 45522682
A41: PUNTO DE EQUILIBRIO EN VENTAS (PDE USD) | B41: =B40/B39 -> 1.2610419e+08
A42: MARGEN DE SEGURIDAD (EN USD) | B42: =B36-B41 -> 4.0013577e+08
A43: MARGEN DE SEGURIDAD (EN %) | B43: =B42/B36 -> 0.76036752
A45: ANÁLISIS:
A46: =+"El cobre vende USD "&ROUND(B36/1000000,2)&" millones y solo necesita USD "&ROUND(B41/1000000,2)&" para cubrir sus costos fijos de USD "&ROUND(B40/1000000,2)&" millones y no perder dinero. El cobre tiene un colchón de USD "&ROUND(B42/1000000,2)&" y sus ventas tendrían que caer más del "&ROUND(B43*100,2)&"% antes de que la linea empiece a generar perdidas." -> El cobre vende USD 526.24 millones y solo necesita USD 126.1 para cubrir sus costos fijos de USD 45.52 millones y no perder dinero. El cobre tiene un colchón de USD 400.14 y sus ventas tendrían que caer más del 76.04% antes de que la linea empiece a generar perdidas.
A49: ANÁLISIS COSTO-VOLUMEN-UTILIDAD Y PUNTO DE EQUILIBRIO CORPORATIVO
...

Sheet PUNTO DE EQUILIBRIO
A1: PUNTO DE EQUILIBRIO (PDE) – COMPAÑÍA DE MINAS BUENAVENTURA S.A.A.
A5: DATOS DE ENTRADA
A6: UNIDAD MINERA | B6: INGRESOS (USD) | C6: COSTO VARIABLE (USD) | D6: MARGEN CONTRIB. (USD) | E6: % MC
A7: ORO | B7: =+'Consolidado x metales'!B4 -> 512087484 | C7: =+'Consolidado x metales'!C4 -> 242590075 | D7: =+Tabla9[[#This Row],[INGRESOS (USD)]]-Tabla9[[#This Row],[COSTO VARIABLE (USD)]] -> 269497409 | E7: =IF(Tabla9[[#This Row],[INGRESOS (USD)]]=0,0,Tabla9[[#This Row],[MARGEN CONTRIB. (USD)]]/Tabla9[[#This Row],[INGRESOS (USD)]]) -> 0.5262722
A8: PLATA | B8: =+'Consolidado x metales'!B5 -> 6.6409999e+08 | C8: =+'Consolidado x metales'!C5 -> 2.8278284e+08 | D8: =+Tabla9[[#This Row],[INGRESOS (USD)]]-Tabla9[[#This Row],[COSTO VARIABLE (USD)]] -> 3.8131715e+08 | E8: =IF(Tabla9[[#This Row],[INGRESOS (USD)]]=0,0,Tabla9[[#This Row],[MARGEN CONTRIB. (USD)]]/Tabla9[[#This Row],[INGRESOS (USD)]]) -> 0.57418635
A9: COBRE | B9: =+'Consolidado x metales'!B6 -> 526239963 | C9: =+'Consolidado x metales'!C6 -> 336271221 | D9: =+Tabla9[[#This Row],[INGRESOS (USD)]]-Tabla9[[#This Row],[COSTO VARIABLE (USD)]] -> 189968742 | E9: =IF(Tabla9[[#This Row],[INGRESOS (USD)]]=0,0,Tabla9[[#This Row],[MARGEN CONTRIB. (USD)]]/Tabla9[[#This Row],[INGRESOS (USD)]]) -> 0.36099262
A10: ZINC | B10: =+'Consolidado x metales'!B8 -> 82532880 | C10: =+'Consolidado x metales'!C8 -> 33883474 | D10: =+Tabla9[[#This Row],[INGRESOS (USD)]]-Tabla9[[#This Row],[COSTO VARIABLE (USD)]] -> 48649406 | E10: =IF(Tabla9[[#This Row],[INGRESOS (USD)]]=0,0,Tabla9[[#This Row],[MARGEN CONTRIB. (USD)]]/Tabla9[[#This Row],[INGRESOS (USD)]]) -> 0.58945485
A11: PLOMO | B11: =+'Consolidado x metales'!B7 -> 37213256 | C11: =+'Consolidado x metales'!C7 -> 13607350 | D11: =+Tabla9[[#This Row],[INGRESOS (USD)]]-Tabla9[[#This Row],[COSTO VARIABLE (USD)]] -> 23605906 | E11: =IF(Tabla9[[#This Row],[INGRESOS (USD)]]=0,0,Tabla9[[#This Row],[MARGEN CONTRIB. (USD)]]/Tabla9[[#This Row],[INGRESOS (USD)]]) -> 0.63434132
A12: TOTAL CONSOLIDADO | B12: =SUM(B7:B11) -> 1.8221736e+09 | C12: =SUM(C7:C11) -> 9.0913496e+08 | D12: =SUM(D7:D11) -> 9.1303861e+08 | E12: =IF(Tabla9[[#This Row],[INGRESOS (USD)]]=0,0,Tabla9[[#This Row],[MARGEN CONTRIB. (USD)]]/Tabla9[[#This Row],[INGRESOS (USD)]]) -> 0.50107115
A15: Costos Fijos Totales Comunes (CF) – USD | B15: {=+Tabla5[VALOR]} -> 289700000
A17: CÁLCULO DEL PUNTO DE EQUILIBRIO
A18: % Margen de Contribución Global (%MC) | B18: =E12 -> 0.50107115
A19: Costos Fijos Totales (CF) | B19: =B15 -> 289700000
A20: PUNTO DE EQUILIBRIO EN VENTAS (PDE, USD) | B20: =B19/B18 -> 5.781614e+08
A21: Ventas actuales (USD) | B21: =B12 -> 1.8221736e+09
A22: Margen de seguridad (USD) | B22: =B21-B20 -> 1.2440122e+09
A23: Margen de seguridad (%) | B23: =IF(B21=0,0,B22/B21) -> 0.68270783
A24: Utilidad operativa a ventas actuales (USD) | B24: =D12-B19 -> 6.2333861e+08
A25: Comprobación: MC en el PDE − CF (debe ser 0) | B25: =ROUND(B20*B18-B19,2) -> 0
A27: INTERPRETACIÓN
A28: ="Buenaventura necesita vender aproximadamente USD "&ROUND(B20/1000000,2)&" millones para cubrir sus costos fijos de USD "&ROUND(B19/1000000,2)&" millones (EBIT = 0). Con ventas de USD "&ROUND(B21/1000000,2)&" millones, sus ventas pueden caer "&ROUND(B23*100,2)&"% antes de entrar en pérdida." -> Buenaventura necesita vender aproximadamente USD 578.16 millones para cubrir sus costos fijos de USD 289.7 millones (EBIT = 0). Con ventas de USD 1822.17 millones, sus ventas pueden caer 68.27% antes de entrar en pérdida.
A31: FIGURA DEL PUNTO DE EQUILIBRIO

Sheet BD PESTEL
A1: Año | B1: Categoría | C1: Indicador Cuantificable | D1: Valor | E1: Unidad
A2: 2015 | B2: Ecológico | C2: Consumo de energía renovable de Buenaventura | D2: 500000 | E2: MWh
A3: 2015 | B3: Ecológico | C3: Emisiones totales de GEI de Buenaventura | D3: 260000 | E3: tCO₂e
A4: 2015 | B4: Económico | C4: Crecimiento del PBI de minería metálica e hidrocarburos | D4: 9.5 | E4: % variación interanual
A5: 2015 | B5: Económico | C5: Inflación – IPC promedio anual | D5: 3.55 | E5: %
A6: 2015 | B6: Económico | C6: Inversión minera del Perú | D6: 6870 | E6: US$ millones
A7: 2015 | B7: Económico | C7: Precio promedio del oro – LBMA | D7: 1159.91 | E7: US$/onza troy
A8: 2015 | B8: Económico | C8: Tipo de cambio promedio | D8: 3.18 | E8: S/ por US$
A9: 2015 | B9: Legal | C9: Calidad regulatoria – WGI | D9: 0.44 | E9: Puntos (-2.5 a 2.5 aprox.)
A10: 2015 | B10: Político | C10: Estabilidad política y ausencia de violencia (percentil WGI) | D10: 60.4 | E10: Percentil
A11: 2015 | B11: Político | C11: Riesgo país EMBIG Perú | D11: 200.7 | E11: Puntos básicos
A12: 2015 | B12: Social | C12: Empleo directo en el sector minero | D12: 183000 | E12: Trabajadores
A13: 2015 | B13: Tecnológico | C13: Inversión minera en equipamiento | D13: 669 | E13: US$ millones
... A132: 2025 | B132: Ecológico | C132: Consumo de energía renovable de Buenaventura | D132: 669556.93 | E132: MWh
A133: 2025 | B133: Ecológico | C133: Emisiones totales de GEI de Buenaventura | E133: tCO₂e
A134: 2025 | B134: Económico | C134: Crecimiento del PBI de minería metálica e hidrocarburos | D134: 1.5 | E134: % variación interanual
A135: 2025 | B135: Económico | C135: Inflación – IPC promedio anual | D135: 1.5 | E135: %
A136: 2025 | B136: Económico | C136: Inversión minera del Perú | D136: 6228 | E136: US$ millones
A137: 2025 | B137: Económico | C137: Precio promedio del oro – LBMA | D137: 3441.58 | E137: US$/onza troy
A138: 2025 | B138: Económico | C138: Tipo de cambio promedio | D138: 3.57 | E138: S/ por US$
A139: 2025 | B139: Legal | C139: Calidad regulatoria – WGI | D139: 0.1 | E139: Puntos (-2.5 a 2.5 aprox.)
A140: 2025 | B140: Político | C140: Estabilidad política y ausencia de violencia (percentil WGI) | D140: 55 | E140: Percentil
A141: 2025 | B141: Político | C141: Riesgo país EMBIG Perú | D141: 145.3 | E141: Puntos básicos
A142: 2025 | B142: Social | C142: Empleo directo en el sector minero | D142: 264054 | E142: Trabajadores
A143: 2025 | B143: Tecnológico | C143: Inversión minera en equipamiento | D143: 1303 | E143: US$ millones
A144: 2025 | B144: Tecnológico | C144: Inversión minera en exploración | D144: 788 | E144: US$ millones

Sheet PRM_Maestro
A1: Mineral | B1: 2018 | C1: 2019 | D1: 2020 | E1: 2021 | F1: 2022 | G1: 2023 | H1: 2024 | I1: 2025
A2: Oro | B2: 0.94 | C2: 0.62 | D2: 0.65 | E2: 0.85 | F2: 0.81 | G2: 0.73 | H2: 0.49 | I2: 0.27
A3: Plata | B3: 1 | C3: 0.94 | D3: 0.67 | E3: 0.47 | F3: 0.31 | G3: 0.23 | H3: 0.86 | I3: 0.79
A4: Cobre | B4: 0.06 | C4: 0.11 | D4: 0.05 | E4: 0.08 | F4: 0.06 | G4: 0.08 | H4: 0.08 | I4: 0.13
A5: Zinc | B5: 0.13 | C5: 0.15 | D5: 0.09 | E5: 0.08 | F5: 0.06 | G5: 0.03 | H5: 0.09 | I5: 0.06
A6: Plomo | B6: 0.76 | C6: 0.77 | D6: 0.56 | E6: 0.35 | F6: 0.25 | G6: 0.14 | H6: 0.31 | I6: 0.29

Sheet BCG_Historica
A1: Año | B1: Mineral | C1: PRM | D1: TCM | E1: Nivel_PRM | F1: Nivel_TCM | G1: Cuadrante
A2: 2019 | B2: Oro | C2: 0.62 | D2: -0.084 | E2: Alto | F2: Bajo | G2: Vaca lechera
A3: 2019 | B3: Plata | C3: 0.94 | D3: -0.072 | E3: Alto | F3: Bajo | G3: Vaca lechera
A4: 2019 | B4: Cobre | C4: 0.11 | D4: 0.008 | E4: Bajo | F4: Bajo | G4: Perro
A5: 2019 | B5: Zinc | C5: 0.15 | D5: -0.047 | E5: Bajo | F5: Bajo | G5: Perro
A6: 2019 | B6: Plomo | C6: 0.77 | D6: 0.066 | E6: Alto | F6: Bajo | G6: Vaca lechera
A7: 2020 | B7: Oro | C7: 0.65 | D7: -0.314 | E7: Alto | F7: Bajo | G7: Vaca lechera
A8: 2020 | B8: Plata | C8: 0.67 | D8: -0.294 | E8: Alto | F8: Bajo | G8: Vaca lechera
A9: 2020 | B9: Cobre | C9: 0.05 | D9: -0.127 | E9: Bajo | F9: Bajo | G9: Perro
A10: 2020 | B10: Zinc | C10: 0.09 | D10: -0.05 | E10: Bajo | F10: Bajo | G10: Perro
A11: 2020 | B11: Plomo | C11: 0.56 | D11: -0.216 | E11: Alto | F11: Bajo | G11: Vaca lechera
A12: 2021 | B12: Oro | C12: 0.85 | D12: 0.107 | E12: Alto | F12: Alto | G12: Estrella
A13: 2021 | B13: Plata | C13: 0.47 | D13: 0.224 | E13: Bajo | F13: Alto | G13: Interrogante
... A36: 2025 | B36: Plomo | C36: 0.29 | D36: 0.086 | E36: Bajo | F36: Bajo | G36: Perro

Sheet Parametros_BCG
A1: Parámetro | B1: Valor | C1: Descripción
A2: Umbral_PRM | B2: 0.5 | C2: PRM > 0.50 = Alto; PRM ≤ 0.50 = Bajo
A3: Umbral_TCM | B3: 0.1 | C3: TCM > 10% = Alto; TCM ≤ 10% = Bajo
A4: Inicio_TCM | B4: 2019 | C4: La TCM 2018 queda vacía porque la serie inicia en 2018.
A5: Inicio_Cuadrante | B5: 2019 | C5: Los cuadrantes BCG se calculan desde 2019.
A6: Formula_PRM | B6: Producción BVN / Producción líder | C6: Participación relativa de Buenaventura frente al líder de cada mineral y año.
A7: Formula_TCM | B7: (Producción BVN_t - Producción BVN_t-1) / Producción BVN_t-1 | C7: Variación interanual de la producción propia de Buenaventura.

Sheet TCM_Maestro
A1: Mineral | B1: 2018 | C1: 2019 | D1: 2020 | E1: 2021 | F1: 2022 | G1: 2023 | H1: 2024 | I1: 2025
A2: Oro | C2: -0.084 | D2: -0.314 | E2: 0.107 | F2: -0.005 | G2: 0.189 | H2: 0.141 | I2: 0.024
A3: Plata | C3: -0.072 | D3: -0.294 | E3: 0.224 | F3: -0.075 | G3: 0.018 | H3: 0.152 | I3: 0.07
A4: Cobre | C4: 0.008 | D4: -0.127 | E4: 0.077 | F4: 0.043 | G4: 0.128 | H4: -0.002 | I4: 0.009
A5: Zinc | C5: -0.047 | D5: -0.05 | E5: 0.149 | F5: -0.107 | G5: 0.073 | H5: -0.135 | I5: 0.188
A6: Plomo | C6: 0.066 | D6: -0.216 | E6: 0.095 | F6: -0.034 | G6: 0.07 | H6: 0.066 | I6: 0.086

Sheet Base_FODA
